<?xml version="1.0" encoding="utf-8"?>
<robot xmlns:xacro="http://www.ros.org/wiki/xacro" name="arm">
    <xacro:macro name="arm">
        <link name="world"></link>
        <link name="base_link">
            <visual>
                <origin xyz="0 0 0" rpy="0 0 0"/>
                <geometry>
                    <mesh filename="package://swing_boy/meshes/base.stl" scale="0.001 0.001 0.001"/>
                </geometry>
            </visual>
            <collision>
                <origin xyz="0. 0. 0." rpy="0 0 0"/>
                <geometry>
                    <mesh filename="package://swing_boy/meshes/base.stl" scale="0.001 0.001 0.001"/>
                </geometry>
            </collision>
            <inertial>
                <mass value="0.476537"/>
                <origin xyz="-0.000051 -0.000125 -0.030648"/>
                <inertia ixx="3.101e-4" ixy="9.215839e-6" ixz="5.46844e-8" iyy="3.100e-4"
                         iyz="-1.59465e-7"
                         izz="4.105e-4"/>
            </inertial>
        </link>
        <joint name="fixed_base" type="fixed">
            <parent link="world"/>
            <child link="base_link"/>
            <origin xyz="0 0 0" rpy="0 0 0"/>
        </joint>
        <link name="link1">
            <visual>
                <origin xyz="0 0 0.032" rpy="0 0 0"/>
                <geometry>
                    <mesh filename="package://swing_boy/meshes/link1.stl" scale="0.001 0.001 0.001"/>
                </geometry>
            </visual>
            <collision>
                <origin xyz="0. 0. 0." rpy="0 0 0"/>
                <geometry>
                    <mesh filename="package://swing_boy/meshes/link1.stl" scale="0.001 0.001 0.001"/>
                </geometry>
            </collision>
            <inertial>
                <mass value="0.499496"/>
                <origin xyz="-0.000017 -0.005388 0.030434"/>
                <inertia ixx="3.043e-4" ixy="7.99033e-7" ixz="1.09468e-7" iyy="2.716e-4"
                         iyz="4.675523e-6"
                         izz="2.922e-4"/>
            </inertial>
        </link>
        <link name="link2">
            <visual>
                <origin xyz="-0.2 0 0" rpy="0 0 0"/>
                <geometry>
                    <mesh filename="package://swing_boy/meshes/link2.stl" scale="0.001 0.001 0.001"/>
                </geometry>
            </visual>
            <collision>
                <origin xyz="-0.2 0. 0." rpy="0 0 0"/>
                <geometry>
                    <mesh filename="package://swing_boy/meshes/link2.stl" scale="0.001 0.001 0.001"/>
                </geometry>
            </collision>
            <inertial>
                <mass value="0.505361"/>
                <origin xyz="-0.191239 -0.005296 0.000049"/>
                <inertia ixx="3.194e-4" ixy="-2.320655e-5" ixz="1.5031e-7" iyy="8.869e-4"
                         iyz="3.28381e-7"
                         izz="9.599e-4"/>
            </inertial>
        </link>
        <link name="link3">
            <visual>
                <origin xyz="0 0 0" rpy="0 0 0"/>
                <geometry>
                    <mesh filename="package://swing_boy/meshes/link3.stl" scale="0.001 0.001 0.001"/>
                </geometry>
            </visual>
            <collision>
                <origin xyz="0. 0. 0." rpy="0 0 0"/>
                <geometry>
                    <mesh filename="package://swing_boy/meshes/link3.stl" scale="0.001 0.001 0.001"/>
                </geometry>
            </collision>
            <inertial>
                <mass value="0.058973"/>
                <origin xyz="0.101968 -0.000085 0.03048"/>
                <inertia ixx="6.4054865e-5" ixy="-5.11151e-7" ixz="-4.1292165e-5"
                         iyy="3.979e-4" iyz="-1.53213e-7"
                         izz="4.306e-4"/>
            </inertial>
        </link>
        <joint name="joint1" type="revolute">
            <parent link="base_link"/>
            <child link="link1"/>
            <origin xyz="0 0 0." rpy="0 0 0"/>
            <axis xyz="0 0 1"/>
            <limit lower="-3.14" upper="3.14" velocity="1" effort="8"/>
        </joint>
        <joint name="joint2" type="revolute">
            <parent link="link1"/>
            <child link="link2"/>
            <origin xyz="0. 0. 0.032" rpy="0 0 0"/>
            <axis xyz="0 1 0"/>
            <limit lower="-3.14" upper="3.14" velocity="1" effort="8"/>
        </joint>
        <joint name="joint3" type="revolute">
            <parent link="link2"/>
            <child link="link3"/>
            <origin xyz="-0.2 0 0" rpy="0 0 0"/>
            <axis xyz="0 1 0"/>
            <limit lower="-3.14" upper="3.14" velocity="1" effort="8"/>
        </joint>

        <link name="EE"/>
        <joint name="EE_fixed" type="fixed">
            <parent link="link3"/>
            <child link="EE"/>
            <origin xyz="0.2 0 0.035" rpy="0 0 0"/>
        </joint>
    </xacro:macro>
</robot>
