<?xml version="1.0" ?>
<!-- =================================================================================== -->
<!-- |    This document was autogenerated by xacro from swing_boy_pro.urdf.xacro       | -->
<!-- |    EDITING THIS FILE BY HAND IS NOT RECOMMENDED                                 | -->
<!-- =================================================================================== -->
<robot name="swing_boy_pro">
  <gazebo>
    <plugin filename="libarm_robot_hw_sim.so" name="arm_ros_control">
      <robotNamespace>/</robotNamespace>
      <robotSimType>arm_gazebo/ArmRobotHWSim</robotSimType>
    </plugin>
  </gazebo>
  <link name="world"/>
  <link name="base_link">
    <visual>
      <origin rpy="0 0 0" xyz="0 0 0"/>
      <geometry>
        <mesh filename="package://swing_boy_pro/meshes/base_link.stl" scale="0.001 0.001 0.001"/>
      </geometry>
    </visual>
    <collision>
      <origin rpy="0 0 0" xyz="0. 0. 0."/>
      <geometry>
        <mesh filename="package://swing_boy_pro/meshes/base_link.stl" scale="0.001 0.001 0.001"/>
      </geometry>
    </collision>
    <inertial>
      <mass value="0.0"/>
      <origin xyz="0.0 0.0 0.0"/>
      <inertia ixx="0" ixy="0.0" ixz="0.0" iyy="0" iyz="0" izz="0"/>
    </inertial>
  </link>
  <joint name="fixed_base" type="fixed">
    <parent link="world"/>
    <child link="base_link"/>
    <origin rpy="0 0 0" xyz="0 0 0"/>
  </joint>
  <link name="link1">
    <visual>
      <origin rpy="0 0 0" xyz="0 0 0"/>
      <geometry>
        <mesh filename="package://swing_boy_pro/meshes/link1.stl" scale="0.001 0.001 0.001"/>
      </geometry>
    </visual>
    <collision>
      <origin rpy="0 0 0" xyz="0. 0. 0."/>
      <geometry>
        <mesh filename="package://swing_boy_pro/meshes/link1.stl" scale="0.001 0.001 0.001"/>
      </geometry>
    </collision>
    <inertial>
      <mass value="0.0"/>
      <origin xyz="0.0 0.0 0.0"/>
      <inertia ixx="0" ixy="0.0" ixz="0.0" iyy="0" iyz="0" izz="0"/>
    </inertial>
  </link>
  <link name="link2">
    <visual>
      <origin rpy="0 0 0" xyz="0 0 0"/>
      <geometry>
        <mesh filename="package://swing_boy_pro/meshes/link2.stl" scale="1 1 1"/>
      </geometry>
    </visual>
    <collision>
      <origin rpy="0 0 0" xyz="0 0. 0."/>
      <geometry>
        <mesh filename="package://swing_boy_pro/meshes/link2.stl" scale="1 1 1"/>
      </geometry>
    </collision>
    <inertial>
      <mass value="0.0"/>
      <origin xyz="0.0 0.0 0.0"/>
      <inertia ixx="0.0" ixy="0.0" ixz="0.0" iyy="0.0" iyz="0.0" izz="0.0"/>
    </inertial>
  </link>
  <link name="link3">
    <visual>
      <origin rpy="0 0 0" xyz="0 0 0"/>
      <geometry>
        <mesh filename="package://swing_boy_pro/meshes/link3.stl" scale="1 1 1"/>
      </geometry>
    </visual>
    <collision>
      <origin rpy="0 0 0" xyz="0. 0. 0."/>
      <geometry>
        <mesh filename="package://swing_boy_pro/meshes/link3.stl" scale="1 1 1"/>
      </geometry>
    </collision>
    <inertial>
      <mass value="0.0"/>
      <origin xyz="0.0 0.0 0.0"/>
      <inertia ixx="0.0" ixy="0.0" ixz="0.0" iyy="0.0" iyz="0.0" izz="0.0"/>
    </inertial>
  </link>
  <link name="link4">
    <visual>
      <origin rpy="0 0 0" xyz="0 0 0"/>
      <geometry>
        <mesh filename="package://swing_boy_pro/meshes/link4.stl" scale="1 1 1"/>
      </geometry>
    </visual>
    <collision>
      <origin rpy="0 0 0" xyz="0. 0. 0."/>
      <geometry>
        <mesh filename="package://swing_boy_pro/meshes/link4.stl" scale="1 1 1"/>
      </geometry>
    </collision>
    <inertial>
      <mass value="0.0"/>
      <origin xyz="0.0 0.0 0.0"/>
      <inertia ixx="0.0" ixy="0.0" ixz="0.0" iyy="0.0" iyz="0.0" izz="0.0"/>
    </inertial>
  </link>
  <link name="link5">
    <visual>
      <origin rpy="0 0 0" xyz="0 0 0"/>
      <geometry>
        <mesh filename="package://swing_boy_pro/meshes/link5.stl" scale="1 1 1"/>
      </geometry>
    </visual>
    <collision>
      <origin rpy="0 0 0" xyz="0 0. 0."/>
      <geometry>
        <mesh filename="package://swing_boy_pro/meshes/link5.stl" scale="1 1 1"/>
      </geometry>
    </collision>
    <inertial>
      <mass value="0.0"/>
      <origin xyz="0.0 0.0 0.0"/>
      <inertia ixx="0.0" ixy="0.0" ixz="0.0" iyy="0.0" iyz="0.0" izz="0.0"/>
    </inertial>
  </link>
  <link name="link6">
    <visual>
      <origin rpy="0 0 0" xyz="0 0 0"/>
      <geometry>
        <mesh filename="package://swing_boy_pro/meshes/link6.stl" scale="0.001 0.001 0.001"/>
      </geometry>
    </visual>
    <collision>
      <origin rpy="0 0 0" xyz="0. 0. 0."/>
      <geometry>
        <mesh filename="package://swing_boy_pro/meshes/link6.stl" scale="0.001 0.001 0.001"/>
      </geometry>
    </collision>
    <inertial>
      <mass value="0.0"/>
      <origin xyz="0.0 0.0 0.0"/>
      <inertia ixx="0.0" ixy="0.0" ixz="0.0" iyy="0.0" iyz="0.0" izz="0.0"/>
    </inertial>
  </link>
  <joint name="joint1" type="revolute">
    <parent link="base_link"/>
    <child link="link1"/>
    <origin rpy="0 0 0" xyz="0.0 0.0 0.08125"/>
    <axis xyz="0 0 1"/>
    <limit effort="8" lower="-3.14" upper="3.14" velocity="1"/>
  </joint>
  <joint name="joint2" type="revolute">
    <parent link="link1"/>
    <child link="link2"/>
    <origin rpy="0 0 0" xyz="0.0 0.0 0.0345"/>
    <axis xyz="0 1 0"/>
    <limit effort="8" lower="-3.14" upper="3.14" velocity="1"/>
  </joint>
  <joint name="joint3" type="revolute">
    <parent link="link2"/>
    <child link="link3"/>
    <origin rpy="0 0 0" xyz="-0.22 0.0 0.0"/>
    <axis xyz="0 1 0"/>
    <limit effort="8" lower="-3.14" upper="3.14" velocity="1"/>
  </joint>
  <joint name="joint4" type="revolute">
    <parent link="link3"/>
    <child link="link4"/>
    <origin rpy="0 0 0" xyz="0.22 0.0 0.0565"/>
    <axis xyz="0 1 0"/>
    <limit effort="8" lower="-3.14" upper="3.14" velocity="1"/>
  </joint>
  <joint name="joint5" type="revolute">
    <parent link="link4"/>
    <child link="link5"/>
    <origin rpy="0 0 0" xyz="0.07 0.038 0.0"/>
    <axis xyz="0 0 1"/>
    <limit effort="8" lower="-3.14" upper="3.14" velocity="1"/>
  </joint>
  <joint name="joint6" type="revolute">
    <parent link="link5"/>
    <child link="link6"/>
    <origin rpy="0 0 0" xyz="0.0265 0.0 -0.038"/>
    <axis xyz="1 0 0"/>
    <limit effort="8" lower="-3.14" upper="3.14" velocity="1"/>
  </joint>
  <link name="EE"/>
  <joint name="EE_fixed" type="fixed">
    <parent link="link6"/>
    <child link="EE"/>
    <origin rpy="0 0 0" xyz="0.2 0 0.035"/>
  </joint>
  <transmission name="trans_joint1">
    <type>transmission_interface/SimpleTransmission</type>
    <actuator name="joint1_motor">
      <mechanicalReduction>1</mechanicalReduction>
    </actuator>
    <joint name="joint1">
      <hardwareInterface>hardware_interface/EffortJointInterface</hardwareInterface>
    </joint>
  </transmission>
  <transmission name="trans_joint2">
    <type>transmission_interface/SimpleTransmission</type>
    <actuator name="joint2_motor">
      <mechanicalReduction>1</mechanicalReduction>
    </actuator>
    <joint name="joint2">
      <hardwareInterface>hardware_interface/EffortJointInterface</hardwareInterface>
    </joint>
  </transmission>
  <transmission name="trans_joint3">
    <type>transmission_interface/SimpleTransmission</type>
    <actuator name="joint3_motor">
      <mechanicalReduction>1</mechanicalReduction>
    </actuator>
    <joint name="joint3">
      <hardwareInterface>hardware_interface/EffortJointInterface</hardwareInterface>
    </joint>
  </transmission>
  <transmission name="trans_joint4">
    <type>transmission_interface/SimpleTransmission</type>
    <actuator name="joint4_motor">
      <mechanicalReduction>1</mechanicalReduction>
    </actuator>
    <joint name="joint4">
      <hardwareInterface>hardware_interface/EffortJointInterface</hardwareInterface>
    </joint>
  </transmission>
  <transmission name="trans_joint5">
    <type>transmission_interface/SimpleTransmission</type>
    <actuator name="joint5_motor">
      <mechanicalReduction>1</mechanicalReduction>
    </actuator>
    <joint name="joint5">
      <hardwareInterface>hardware_interface/EffortJointInterface</hardwareInterface>
    </joint>
  </transmission>
  <transmission name="trans_joint6">
    <type>transmission_interface/SimpleTransmission</type>
    <actuator name="joint6_motor">
      <mechanicalReduction>1</mechanicalReduction>
    </actuator>
    <joint name="joint6">
      <hardwareInterface>hardware_interface/EffortJointInterface</hardwareInterface>
    </joint>
  </transmission>
  <!--        <transmission name="trans_EE">-->
  <!--            <type>transmission_interface/SimpleTransmission</type>-->
  <!--            <actuator name="EE_joint_motor">-->
  <!--                <mechanicalReduction>-1</mechanicalReduction>-->
  <!--            </actuator>-->
  <!--            <joint name="EE_joint">-->
  <!--                <hardwareInterface>hardware_interface/EffortJointInterface</hardwareInterface>-->
  <!--            </joint>-->
  <!--        </transmission>-->
</robot>
