<?xml version="1.0" ?>
<!-- =================================================================================== -->
<!-- |    This document was autogenerated by xacro from delta.urdf.xacro               | -->
<!-- |    EDITING THIS FILE BY HAND IS NOT RECOMMENDED                                 | -->
<!-- =================================================================================== -->
<robot name="delta">
  <gazebo>
    <plugin filename="libarm_robot_hw_sim.so" name="arm_ros_control">
      <robotNamespace>/</robotNamespace>
      <robotSimType>arm_gazebo/ArmRobotHWSim</robotSimType>
    </plugin>
  </gazebo>
  <link name="world"/>
  <link name="base_link">
    <visual>
      <origin rpy="0 0 0" xyz="0 0 0"/>
      <geometry>
        <mesh filename="package://delta/meshes/base_link.stl" scale="0.001 0.001 0.001"/>
      </geometry>
    </visual>
    <collision>
      <origin rpy="0 0 0" xyz="0. 0 0."/>
      <geometry>
        <mesh filename="package://delta/meshes/base_link.stl" scale="0.0001 0.0001 0.0001"/>
      </geometry>
    </collision>
    <inertial>
      <mass value="0.101"/>
      <origin xyz="0.0 0.0 -0.0015"/>
      <inertia ixx="3.5130112e-05" ixy="0.0" ixz="7.391e-19" iyy="3.5130112e-05" iyz="0.0" izz="7.0108029e-05"/>
    </inertial>
  </link>
  <joint name="fix_base" type="fixed">
    <parent link="world"/>
    <child link="base_link"/>
    <origin rpy="0 0 0" xyz="0. 0. 0."/>
  </joint>
  <link name="active_arm_1">
    <visual>
      <origin rpy="0 0 0" xyz="0 0 0"/>
      <geometry>
        <mesh filename="package://delta/meshes/active_arm.stl" scale="0.001 0.001 0.001"/>
      </geometry>
    </visual>
    <collision>
      <origin rpy="0 0 0" xyz="0. 0. 0."/>
      <geometry>
        <mesh filename="package://delta/meshes/active_arm.stl" scale="0.0001 0.0001 0.0001"/>
      </geometry>
    </collision>
    <inertial>
      <mass value="0.00457"/>
      <origin xyz="0.0 -0.042671 0.0"/>
      <inertia ixx="4.714e-06" ixy="0.0" ixz="0.0" iyy="2.577e-08" iyz="-8.235e-18" izz="4.707e-06"/>
    </inertial>
  </link>
  <link name="parallel_up_1">
    <visual>
      <origin rpy="0 0 0" xyz="0 0 0"/>
      <geometry>
        <mesh filename="package://delta/meshes/parallel_up.stl" scale="0.001 0.001 0.001"/>
      </geometry>
    </visual>
    <collision>
      <origin rpy="0 0 0" xyz="0. 0 0."/>
      <geometry>
        <mesh filename="package://delta/meshes/parallel_up.stl" scale="0.0001 0.0001 0.0001"/>
      </geometry>
    </collision>
    <inertial>
      <mass value="0.027"/>
      <origin xyz="0.0 0.0 0.0"/>
      <inertia ixx="3.16967e-07" ixy="0.0" ixz="0.0" iyy="5.926399e-06" iyz="2.4474e-08" izz="5.898139e-06"/>
    </inertial>
  </link>
  <link name="passive_arm_1">
    <visual>
      <origin rpy="0 0 0" xyz="0 0 0"/>
      <geometry>
        <mesh filename="package://delta/meshes/passive_arm.stl" scale="0.001 0.001 0.001"/>
      </geometry>
    </visual>
    <collision>
      <origin rpy="0 0 0" xyz="0 0 0"/>
      <geometry>
        <mesh filename="package://delta/meshes/passive_arm.stl" scale="0.0001 0.0001 0.0001"/>
      </geometry>
    </collision>
    <inertial>
      <mass value="0.011"/>
      <origin xyz="-0.00168 0.096 0.0"/>
      <inertia ixx="4.4636101e-05" ixy="7.8174e-08" ixz="0.0" iyy="8.2492e-08" iyz="1.379e-19" izz="4.4642e-05"/>
    </inertial>
  </link>
  <link name="parallel_down_1">
    <visual>
      <origin rpy="0 0 0" xyz="0 0 0"/>
      <geometry>
        <mesh filename="package://delta/meshes/parallel_down.stl" scale="0.001 0.001 0.001"/>
      </geometry>
    </visual>
    <collision>
      <origin rpy="0 0 0" xyz="0 0 0"/>
      <geometry>
        <mesh filename="package://delta/meshes/parallel_down.stl" scale="0.0001 0.0001 0.0001"/>
      </geometry>
    </collision>
    <inertial>
      <mass value="0.027"/>
      <origin xyz="0.0 0.0 0.0"/>
      <inertia ixx="3.16967e-07" ixy="1.095e-10" ixz="1.29e-10" iyy="5.926399e-06" iyz="2.4474e-08" izz="5.898139e-06"/>
    </inertial>
  </link>
  <link name="move_base_1">
    <visual>
      <origin rpy="0 0 0" xyz="0 0 0"/>
      <geometry>
        <mesh filename="package://delta/meshes/move_base.stl" scale="0.001 0.001 0.001"/>
      </geometry>
    </visual>
    <collision>
      <origin rpy="0 0 0" xyz="0 0 0"/>
      <geometry>
        <mesh filename="package://delta/meshes/move_base.stl" scale="0.0001 0.0001 0.0001"/>
      </geometry>
    </collision>
    <inertial>
      <mass value="0.007"/>
      <origin xyz="0.0 0.012536 0.0"/>
      <inertia ixx="4.91052e-07" ixy="0.0" ixz="0.0" iyy="6.2663e-08" iyz="3.4e-11" izz="4.59974e-07"/>
    </inertial>
  </link>
  <joint name="active_joint1" type="revolute">
    <parent link="base_link"/>
    <child link="active_arm_1"/>
    <origin rpy="0 0 0" xyz="0 -0.040721 0"/>
    <axis xyz="1 0 0"/>
    <limit effort="1" lower="-3.14" upper="3.14" velocity="30"/>
  </joint>
  <joint name="parallel_up_a_joint1" type="revolute">
    <parent link="active_arm_1"/>
    <child link="parallel_up_1"/>
    <origin rpy="-1.04619753 0 0" xyz="0 -0.09 0"/>
    <axis xyz="1 0 0"/>
    <limit effort="1" lower="-3.14" upper="3.14" velocity="1"/>
  </joint>
  <joint name="parallel_up_b_joint1" type="revolute">
    <parent link="parallel_up_1"/>
    <child link="passive_arm_1"/>
    <origin rpy="0. 0 0" xyz="0 0 0"/>
    <axis xyz="0 0 1"/>
    <limit effort="1" lower="-3.14" upper="3.14" velocity="1"/>
  </joint>
  <joint name="parallel_down_b_joint1" type="revolute">
    <parent link="passive_arm_1"/>
    <child link="parallel_down_1"/>
    <origin rpy="0 0 0" xyz="0 0.192 0"/>
    <axis xyz="0 0 1"/>
    <limit effort="1" lower="-3.14" upper="3.14" velocity="1"/>
  </joint>
  <joint name="parallel_down_a_joint1" type="revolute">
    <parent link="parallel_down_1"/>
    <child link="move_base_1"/>
    <origin rpy="1.04619753 0 0" xyz="0 0 0"/>
    <axis xyz="1 0 0"/>
    <limit effort="1" lower="-3.14" upper="3.14" velocity="1"/>
  </joint>
  <link name="active_arm_2">
    <visual>
      <origin rpy="0 0 0" xyz="0 0 0"/>
      <geometry>
        <mesh filename="package://delta/meshes/active_arm.stl" scale="0.001 0.001 0.001"/>
      </geometry>
    </visual>
    <collision>
      <origin rpy="0 0 0" xyz="0. 0. 0."/>
      <geometry>
        <mesh filename="package://delta/meshes/active_arm.stl" scale="0.0001 0.0001 0.0001"/>
      </geometry>
    </collision>
    <inertial>
      <mass value="0.00457"/>
      <origin xyz="0.0 -0.042671 0.0"/>
      <inertia ixx="4.714e-06" ixy="0.0" ixz="0.0" iyy="2.577e-08" iyz="-8.235e-18" izz="4.707e-06"/>
    </inertial>
  </link>
  <link name="parallel_up_2">
    <visual>
      <origin rpy="0 0 0" xyz="0 0 0"/>
      <geometry>
        <mesh filename="package://delta/meshes/parallel_up.stl" scale="0.001 0.001 0.001"/>
      </geometry>
    </visual>
    <collision>
      <origin rpy="0 0 0" xyz="0. 0 0."/>
      <geometry>
        <mesh filename="package://delta/meshes/parallel_up.stl" scale="0.0001 0.0001 0.0001"/>
      </geometry>
    </collision>
    <inertial>
      <mass value="0.027"/>
      <origin xyz="0.0 0.0 0.0"/>
      <inertia ixx="3.16967e-07" ixy="0.0" ixz="0.0" iyy="5.926399e-06" iyz="2.4474e-08" izz="5.898139e-06"/>
    </inertial>
  </link>
  <link name="passive_arm_2">
    <visual>
      <origin rpy="0 0 0" xyz="0 0 0"/>
      <geometry>
        <mesh filename="package://delta/meshes/passive_arm.stl" scale="0.001 0.001 0.001"/>
      </geometry>
    </visual>
    <collision>
      <origin rpy="0 0 0" xyz="0 0 0"/>
      <geometry>
        <mesh filename="package://delta/meshes/passive_arm.stl" scale="0.0001 0.0001 0.0001"/>
      </geometry>
    </collision>
    <inertial>
      <mass value="0.011"/>
      <origin xyz="-0.00168 0.096 0.0"/>
      <inertia ixx="4.4636101e-05" ixy="7.8174e-08" ixz="0.0" iyy="8.2492e-08" iyz="1.379e-19" izz="4.4642e-05"/>
    </inertial>
  </link>
  <link name="parallel_down_2">
    <visual>
      <origin rpy="0 0 0" xyz="0 0 0"/>
      <geometry>
        <mesh filename="package://delta/meshes/parallel_down.stl" scale="0.001 0.001 0.001"/>
      </geometry>
    </visual>
    <collision>
      <origin rpy="0 0 0" xyz="0 0 0"/>
      <geometry>
        <mesh filename="package://delta/meshes/parallel_down.stl" scale="0.0001 0.0001 0.0001"/>
      </geometry>
    </collision>
    <inertial>
      <mass value="0.027"/>
      <origin xyz="0.0 0.0 0.0"/>
      <inertia ixx="3.16967e-07" ixy="1.095e-10" ixz="1.29e-10" iyy="5.926399e-06" iyz="2.4474e-08" izz="5.898139e-06"/>
    </inertial>
  </link>
  <link name="move_base_2">
    <visual>
      <origin rpy="0 0 0" xyz="0 0 0"/>
      <geometry>
        <mesh filename="package://delta/meshes/move_base.stl" scale="0.001 0.001 0.001"/>
      </geometry>
    </visual>
    <collision>
      <origin rpy="0 0 0" xyz="0 0 0"/>
      <geometry>
        <mesh filename="package://delta/meshes/move_base.stl" scale="0.0001 0.0001 0.0001"/>
      </geometry>
    </collision>
    <inertial>
      <mass value="0.007"/>
      <origin xyz="0.0 0.012536 0.0"/>
      <inertia ixx="4.91052e-07" ixy="0.0" ixz="0.0" iyy="6.2663e-08" iyz="3.4e-11" izz="4.59974e-07"/>
    </inertial>
  </link>
  <joint name="active_joint2" type="revolute">
    <parent link="base_link"/>
    <child link="active_arm_2"/>
    <origin rpy="0 0 -2.09439504" xyz="-0.03526542046750613 0.020360499999999997 0."/>
    <axis xyz="1 0 0"/>
    <limit effort="1" lower="-3.14" upper="3.14" velocity="30"/>
  </joint>
  <joint name="parallel_up_a_joint2" type="revolute">
    <parent link="active_arm_2"/>
    <child link="parallel_up_2"/>
    <origin rpy="-1.04619753 0 0" xyz="0 -0.09 0"/>
    <axis xyz="1 0 0"/>
    <limit effort="1" lower="-3.14" upper="3.14" velocity="1"/>
  </joint>
  <joint name="parallel_up_b_joint2" type="revolute">
    <parent link="parallel_up_2"/>
    <child link="passive_arm_2"/>
    <origin rpy="0 0 0" xyz="0 0 0"/>
    <axis xyz="0 0 1"/>
    <limit effort="1" lower="-3.14" upper="3.14" velocity="1"/>
  </joint>
  <joint name="parallel_down_b_joint2" type="revolute">
    <parent link="passive_arm_2"/>
    <child link="parallel_down_2"/>
    <origin rpy="0 0 0" xyz="0 0.192 0."/>
    <axis xyz="0 0 1"/>
    <limit effort="1" lower="-3.14" upper="3.14" velocity="1"/>
  </joint>
  <joint name="parallel_down_a_joint2" type="revolute">
    <parent link="parallel_down_2"/>
    <child link="move_base_2"/>
    <origin rpy="1.04619753 0 0" xyz="0 0 0"/>
    <axis xyz="1 0 0"/>
    <limit effort="1" lower="-3.14" upper="3.14" velocity="1"/>
  </joint>
  <link name="active_arm_3">
    <visual>
      <origin rpy="0 0 0" xyz="0 0 0"/>
      <geometry>
        <mesh filename="package://delta/meshes/active_arm.stl" scale="0.001 0.001 0.001"/>
      </geometry>
    </visual>
    <collision>
      <origin rpy="0 0 0" xyz="0. 0. 0."/>
      <geometry>
        <mesh filename="package://delta/meshes/active_arm.stl" scale="0.0001 0.0001 0.0001"/>
      </geometry>
    </collision>
    <inertial>
      <mass value="0.00457"/>
      <origin xyz="0.0 -0.042671 0.0"/>
      <inertia ixx="4.714e-06" ixy="0.0" ixz="0.0" iyy="2.577e-08" iyz="-8.235e-18" izz="4.707e-06"/>
    </inertial>
  </link>
  <link name="parallel_up_3">
    <visual>
      <origin rpy="0 0 0" xyz="0 0 0"/>
      <geometry>
        <mesh filename="package://delta/meshes/parallel_up.stl" scale="0.001 0.001 0.001"/>
      </geometry>
    </visual>
    <collision>
      <origin rpy="0 0 0" xyz="0. 0 0."/>
      <geometry>
        <mesh filename="package://delta/meshes/parallel_up.stl" scale="0.0001 0.0001 0.0001"/>
      </geometry>
    </collision>
    <inertial>
      <mass value="0.027"/>
      <origin xyz="0.0 0.0 0.0"/>
      <inertia ixx="3.16967e-07" ixy="0.0" ixz="0.0" iyy="5.926399e-06" iyz="2.4474e-08" izz="5.898139e-06"/>
    </inertial>
  </link>
  <link name="passive_arm_3">
    <visual>
      <origin rpy="0 0 0" xyz="0 0 0"/>
      <geometry>
        <mesh filename="package://delta/meshes/passive_arm.stl" scale="0.001 0.001 0.001"/>
      </geometry>
    </visual>
    <collision>
      <origin rpy="0 0 0" xyz="0 0 0"/>
      <geometry>
        <mesh filename="package://delta/meshes/passive_arm.stl" scale="0.0001 0.0001 0.0001"/>
      </geometry>
    </collision>
    <inertial>
      <mass value="0.011"/>
      <origin xyz="-0.00168 0.096 0.0"/>
      <inertia ixx="4.4636101e-05" ixy="7.8174e-08" ixz="0.0" iyy="8.2492e-08" iyz="1.379e-19" izz="4.4642e-05"/>
    </inertial>
  </link>
  <link name="parallel_down_3">
    <visual>
      <origin rpy="0 0 0" xyz="0 0 0"/>
      <geometry>
        <mesh filename="package://delta/meshes/parallel_down.stl" scale="0.001 0.001 0.001"/>
      </geometry>
    </visual>
    <collision>
      <origin rpy="0 0 0" xyz="0 0 0"/>
      <geometry>
        <mesh filename="package://delta/meshes/parallel_down.stl" scale="0.0001 0.0001 0.0001"/>
      </geometry>
    </collision>
    <inertial>
      <mass value="0.027"/>
      <origin xyz="0.0 0.0 0.0"/>
      <inertia ixx="3.16967e-07" ixy="1.095e-10" ixz="1.29e-10" iyy="5.926399e-06" iyz="2.4474e-08" izz="5.898139e-06"/>
    </inertial>
  </link>
  <link name="move_base_3">
    <visual>
      <origin rpy="0 0 0" xyz="0 0 0"/>
      <geometry>
        <mesh filename="package://delta/meshes/move_base.stl" scale="0.001 0.001 0.001"/>
      </geometry>
    </visual>
    <collision>
      <origin rpy="0 0 0" xyz="0 0 0"/>
      <geometry>
        <mesh filename="package://delta/meshes/move_base.stl" scale="0.0001 0.0001 0.0001"/>
      </geometry>
    </collision>
    <inertial>
      <mass value="0.007"/>
      <origin xyz="0.0 0.012536 0.0"/>
      <inertia ixx="4.91052e-07" ixy="0.0" ixz="0.0" iyy="6.2663e-08" iyz="3.4e-11" izz="4.59974e-07"/>
    </inertial>
  </link>
  <joint name="active_joint3" type="revolute">
    <parent link="base_link"/>
    <child link="active_arm_3"/>
    <origin rpy="0 0 2.09439504" xyz="0.03526542046750613 0.020360499999999997 0."/>
    <axis xyz="1 0 0"/>
    <limit effort="1" lower="-3.14" upper="3.14" velocity="30"/>
  </joint>
  <joint name="parallel_up_a_joint3" type="revolute">
    <parent link="active_arm_3"/>
    <child link="parallel_up_3"/>
    <origin rpy="-1.04619753 0 0" xyz="0 -0.09 0"/>
    <axis xyz="1 0 0"/>
    <limit effort="1" lower="-3.14" upper="3.14" velocity="1"/>
  </joint>
  <joint name="parallel_up_b_joint3" type="revolute">
    <parent link="parallel_up_3"/>
    <child link="passive_arm_3"/>
    <origin rpy="0 0 0" xyz="0 0 0"/>
    <axis xyz="0 0 1"/>
    <limit effort="1" lower="-3.14" upper="3.14" velocity="1"/>
  </joint>
  <joint name="parallel_down_b_joint3" type="revolute">
    <parent link="passive_arm_3"/>
    <child link="parallel_down_3"/>
    <origin rpy="0 0 0" xyz="0 0.192 0."/>
    <axis xyz="0 0 1"/>
    <limit effort="1" lower="-3.14" upper="3.14" velocity="1"/>
  </joint>
  <joint name="parallel_down_a_joint3" type="revolute">
    <parent link="parallel_down_3"/>
    <child link="move_base_3"/>
    <origin rpy="1.04619753 0 0" xyz="0 0 0"/>
    <axis xyz="1 0 0"/>
    <limit effort="1" lower="-3.14" upper="3.14" velocity="1"/>
  </joint>
  <link name="move_EE">
    <visual>
      <origin rpy="0 0 0" xyz="0 0 0"/>
      <geometry>
        <mesh filename="package://delta/meshes/move_EE.stl" scale="0.001 0.001 0.001"/>
      </geometry>
    </visual>
    <collision>
      <origin rpy="0 0 0" xyz="0. 0 0."/>
      <geometry>
        <mesh filename="package://delta/meshes/move_EE.stl" scale="0.001 0.001 0.001"/>
      </geometry>
    </collision>
    <inertial>
      <mass value="0.01"/>
      <origin xyz="0.0 0.0 0.0"/>
      <inertia ixx="0.0" ixy="0.0" ixz="0.0" iyy="0.0" iyz="0.0" izz="0.0"/>
    </inertial>
  </link>
  <joint name="con_move_base_EE_1" type="fixed">
    <parent link="move_base_1"/>
    <child link="move_EE"/>
    <origin rpy="0 0 0" xyz="0. 0.03465 0."/>
  </joint>
  <gazebo>
    <joint name="con_move_base_EE_2" type="fixed">
      <parent>move_base_2</parent>
      <child>move_EE</child>
      <origin rpy="0 0 0" xyz="0. 0.03465 0."/>
    </joint>
    <joint name="con_move_base_EE_3" type="fixed">
      <parent>move_base_3</parent>
      <child>move_EE</child>
      <origin rpy="0 0 0" xyz="0. 0.03465 0."/>
    </joint>
  </gazebo>
  <link name="computer_EE">
    <visual>
      <origin rpy="0 0 0" xyz="0 0 0"/>
      <geometry>
        <sphere radius="0.001"/>
      </geometry>
    </visual>
    <inertial>
      <mass value="0.01"/>
      <origin xyz="0.0 0.0 0.0"/>
      <inertia ixx="0.0" ixy="0.0" ixz="0.0" iyy="0.0" iyz="0.0" izz="0.0"/>
    </inertial>
  </link>
  <link name="computer_x">
    <visual>
      <origin rpy="0 0 0" xyz="0 0 0"/>
      <geometry>
        <sphere radius="0.001"/>
      </geometry>
    </visual>
    <inertial>
      <mass value="0.01"/>
      <origin xyz="0.0 0.0 0.0"/>
      <inertia ixx="0.0" ixy="0.0" ixz="0.0" iyy="0.0" iyz="0.0" izz="0.0"/>
    </inertial>
  </link>
  <link name="computer_y">
    <visual>
      <origin rpy="0 0 0" xyz="0 0 0"/>
      <geometry>
        <sphere radius="0.001"/>
      </geometry>
    </visual>
    <inertial>
      <mass value="0.01"/>
      <origin xyz="0.0 0.0 0.0"/>
      <inertia ixx="0.0" ixy="0.0" ixz="0.0" iyy="0.0" iyz="0.0" izz="0.0"/>
    </inertial>
  </link>
  <joint name="computer_x_joint" type="prismatic">
    <parent link="base_link"/>
    <child link="computer_x"/>
    <origin rpy="0 0 0" xyz="0. 0. 0."/>
    <axis xyz="1 0 0"/>
    <limit effort="10" lower="-100" upper="100" velocity="10"/>
  </joint>
  <joint name="computer_y_joint" type="prismatic">
    <parent link="computer_x"/>
    <child link="computer_y"/>
    <origin rpy="0 0 0" xyz="0. 0. 0."/>
    <axis xyz="0 1 0"/>
    <limit effort="10" lower="-100" upper="100" velocity="10"/>
  </joint>
  <joint name="computer_EE_joint" type="prismatic">
    <parent link="computer_y"/>
    <child link="computer_EE"/>
    <origin rpy="0 0 0" xyz="0. 0. 0."/>
    <axis xyz="0 0 1"/>
    <limit effort="10" lower="-100" upper="100" velocity="10"/>
  </joint>
  <transmission name="trans_active_joint1">
    <type>transmission_interface/SimpleTransmission</type>
    <actuator name="active_joint1_motor">
      <mechanicalReduction>-1</mechanicalReduction>
    </actuator>
    <joint name="active_joint1">
      <offset>-0.437579</offset>
      <hardwareInterface>hardware_interface/EffortJointInterface</hardwareInterface>
    </joint>
  </transmission>
  <transmission name="trans_parallel_up_a_joint1">
    <type>transmission_interface/SimpleTransmission</type>
    <actuator name="parallel_up_a_joint1_motor">
      <mechanicalReduction>1</mechanicalReduction>
    </actuator>
    <joint name="parallel_up_a_joint1">
      <hardwareInterface>hardware_interface/EffortJointInterface</hardwareInterface>
    </joint>
  </transmission>
  <transmission name="trans_parallel_up_b_joint1">
    <type>transmission_interface/SimpleTransmission</type>
    <actuator name="parallel_up_b_joint1_motor">
      <mechanicalReduction>1</mechanicalReduction>
    </actuator>
    <joint name="parallel_up_b_joint1">
      <hardwareInterface>hardware_interface/EffortJointInterface</hardwareInterface>
    </joint>
  </transmission>
  <transmission name="trans_parallel_down_a_joint1">
    <type>transmission_interface/SimpleTransmission</type>
    <actuator name="parallel_down_a_joint1_motor">
      <mechanicalReduction>1</mechanicalReduction>
    </actuator>
    <joint name="parallel_down_a_joint1">
      <hardwareInterface>hardware_interface/EffortJointInterface</hardwareInterface>
    </joint>
  </transmission>
  <transmission name="trans_parallel_down_b_joint1">
    <type>transmission_interface/SimpleTransmission</type>
    <actuator name="parallel_down_b_joint1_motor">
      <mechanicalReduction>1</mechanicalReduction>
    </actuator>
    <joint name="parallel_down_b_joint1">
      <hardwareInterface>hardware_interface/EffortJointInterface</hardwareInterface>
    </joint>
  </transmission>
  <transmission name="trans_active_joint2">
    <type>transmission_interface/SimpleTransmission</type>
    <actuator name="active_joint2_motor">
      <mechanicalReduction>-1</mechanicalReduction>
    </actuator>
    <joint name="active_joint2">
      <offset>-0.437579</offset>
      <hardwareInterface>hardware_interface/EffortJointInterface</hardwareInterface>
    </joint>
  </transmission>
  <transmission name="trans_parallel_up_a_joint2">
    <type>transmission_interface/SimpleTransmission</type>
    <actuator name="parallel_up_a_joint2_motor">
      <mechanicalReduction>1</mechanicalReduction>
    </actuator>
    <joint name="parallel_up_a_joint2">
      <hardwareInterface>hardware_interface/EffortJointInterface</hardwareInterface>
    </joint>
  </transmission>
  <transmission name="trans_parallel_up_b_joint2">
    <type>transmission_interface/SimpleTransmission</type>
    <actuator name="parallel_up_b_joint2_motor">
      <mechanicalReduction>1</mechanicalReduction>
    </actuator>
    <joint name="parallel_up_b_joint2">
      <hardwareInterface>hardware_interface/EffortJointInterface</hardwareInterface>
    </joint>
  </transmission>
  <transmission name="trans_parallel_down_a_joint2">
    <type>transmission_interface/SimpleTransmission</type>
    <actuator name="parallel_down_a_joint2_motor">
      <mechanicalReduction>1</mechanicalReduction>
    </actuator>
    <joint name="parallel_down_a_joint2">
      <hardwareInterface>hardware_interface/EffortJointInterface</hardwareInterface>
    </joint>
  </transmission>
  <transmission name="trans_parallel_down_b_joint2">
    <type>transmission_interface/SimpleTransmission</type>
    <actuator name="parallel_down_b_joint2_motor">
      <mechanicalReduction>1</mechanicalReduction>
    </actuator>
    <joint name="parallel_down_b_joint2">
      <hardwareInterface>hardware_interface/EffortJointInterface</hardwareInterface>
    </joint>
  </transmission>
  <transmission name="trans_active_joint3">
    <type>transmission_interface/SimpleTransmission</type>
    <actuator name="active_joint3_motor">
      <mechanicalReduction>-1</mechanicalReduction>
    </actuator>
    <joint name="active_joint3">
      <offset>-0.437579</offset>
      <hardwareInterface>hardware_interface/EffortJointInterface</hardwareInterface>
    </joint>
  </transmission>
  <transmission name="trans_parallel_up_a_joint3">
    <type>transmission_interface/SimpleTransmission</type>
    <actuator name="parallel_up_a_joint3_motor">
      <mechanicalReduction>1</mechanicalReduction>
    </actuator>
    <joint name="parallel_up_a_joint3">
      <hardwareInterface>hardware_interface/EffortJointInterface</hardwareInterface>
    </joint>
  </transmission>
  <transmission name="trans_parallel_up_b_joint3">
    <type>transmission_interface/SimpleTransmission</type>
    <actuator name="parallel_up_b_joint3_motor">
      <mechanicalReduction>1</mechanicalReduction>
    </actuator>
    <joint name="parallel_up_b_joint3">
      <hardwareInterface>hardware_interface/EffortJointInterface</hardwareInterface>
    </joint>
  </transmission>
  <transmission name="trans_parallel_down_a_joint3">
    <type>transmission_interface/SimpleTransmission</type>
    <actuator name="parallel_down_a_joint3_motor">
      <mechanicalReduction>1</mechanicalReduction>
    </actuator>
    <joint name="parallel_down_a_joint3">
      <hardwareInterface>hardware_interface/EffortJointInterface</hardwareInterface>
    </joint>
  </transmission>
  <transmission name="trans_parallel_down_b_joint3">
    <type>transmission_interface/SimpleTransmission</type>
    <actuator name="parallel_down_b_joint3_motor">
      <mechanicalReduction>1</mechanicalReduction>
    </actuator>
    <joint name="parallel_down_b_joint3">
      <hardwareInterface>hardware_interface/EffortJointInterface</hardwareInterface>
    </joint>
  </transmission>
  <transmission name="trans_computer_x_joint">
    <type>transmission_interface/SimpleTransmission</type>
    <actuator name="computer_x_joint_motor">
      <mechanicalReduction>1</mechanicalReduction>
    </actuator>
    <joint name="computer_x_joint">
      <hardwareInterface>hardware_interface/EffortJointInterface</hardwareInterface>
    </joint>
  </transmission>
  <transmission name="trans_computer_y_joint">
    <type>transmission_interface/SimpleTransmission</type>
    <actuator name="computer_y_joint_motor">
      <mechanicalReduction>1</mechanicalReduction>
    </actuator>
    <joint name="computer_y_joint">
      <hardwareInterface>hardware_interface/EffortJointInterface</hardwareInterface>
    </joint>
  </transmission>
  <transmission name="trans_computer_EE_joint">
    <type>transmission_interface/SimpleTransmission</type>
    <actuator name="computer_EE_joint_motor">
      <mechanicalReduction>1</mechanicalReduction>
    </actuator>
    <joint name="computer_EE_joint">
      <hardwareInterface>hardware_interface/EffortJointInterface</hardwareInterface>
    </joint>
  </transmission>
</robot>
